Workbook

Sheet RESUMO ANUAL
A1: MÊS | B1: ENTRADAS | C1: SAÍDAS | D1: INVESTIMENTOS | E1: SONHOS
A2: 46023 | B2: =ABS(SUMIFS( JANEIRO2026!G:G, JANEIRO2026!B:B,"Entrada" )) -> 0 | C2: =ABS(SUMIFS( JANEIRO2026!G:G, JANEIRO2026!B:B,"Saída" )) -> 287.24 | D2: =SUMIFS(JANEIRO2026!$F:$F,JANEIRO2026!$Y:$Y,"Investimento")+SUMIFS(JANEIRO2026!$F:$F,JANEIRO2026!$D:$D,"Investimentos",JANEIRO2026!$X:$X,"" ) -> 100 | E2: =SUMIFS(JANEIRO2026!$F:$F,JANEIRO2026!$Y:$Y,"Aporte para sonho")+SUMIFS(JANEIRO2026!$F:$F,JANEIRO2026!$D:$D,"Sonhos",JANEIRO2026!$X:$X,"" ) -> 100
A3: 46054 | D3: =SUMIFS(FEVEREIRO2026!$F:$F,FEVEREIRO2026!$Y:$Y,"Investimento")+SUMIFS(FEVEREIRO2026!$F:$F,FEVEREIRO2026!$D:$D,"Investimentos",FEVEREIRO2026!$X:$X,"" ) -> 0 | E3: =SUMIFS(FEVEREIRO2026!$F:$F,FEVEREIRO2026!$Y:$Y,"Aporte para sonho")+SUMIFS(FEVEREIRO2026!$F:$F,FEVEREIRO2026!$D:$D,"Sonhos",FEVEREIRO2026!$X:$X,"" ) -> 0
A4: 46082 | D4: =SUMIFS(MARÇO2026!$F:$F,MARÇO2026!$Y:$Y,"Investimento")+SUMIFS(MARÇO2026!$F:$F,MARÇO2026!$D:$D,"Investimentos",MARÇO2026!$X:$X,"" ) -> 0 | E4: =SUMIFS(MARÇO2026!$F:$F,MARÇO2026!$Y:$Y,"Aporte para sonho")+SUMIFS(MARÇO2026!$F:$F,MARÇO2026!$D:$D,"Sonhos",MARÇO2026!$X:$X,"" ) -> 0
A5: 46113 | D5: =SUMIFS(ABRIL2026!$F:$F,ABRIL2026!$Y:$Y,"Investimento")+SUMIFS(ABRIL2026!$F:$F,ABRIL2026!$D:$D,"Investimentos",ABRIL2026!$X:$X,"" ) -> 0 | E5: =SUMIFS(ABRIL2026!$F:$F,ABRIL2026!$Y:$Y,"Aporte para sonho")+SUMIFS(ABRIL2026!$F:$F,ABRIL2026!$D:$D,"Sonhos",ABRIL2026!$X:$X,"" ) -> 0
A6: 46143 | D6: =SUMIFS(MAIO2026!$F:$F,MAIO2026!$Y:$Y,"Investimento")+SUMIFS(MAIO2026!$F:$F,MAIO2026!$D:$D,"Investimentos",MAIO2026!$X:$X,"" ) -> 1346 | E6: =SUMIFS(MAIO2026!$F:$F,MAIO2026!$Y:$Y,"Aporte para sonho")+SUMIFS(MAIO2026!$F:$F,MAIO2026!$D:$D,"Sonhos",MAIO2026!$X:$X,"" ) -> 0
A7: 46174 | D7: =SUMIFS(JUNHO2026!$F:$F,JUNHO2026!$Y:$Y,"Investimento")+SUMIFS(JUNHO2026!$F:$F,JUNHO2026!$D:$D,"Investimentos",JUNHO2026!$X:$X,"" ) -> 0 | E7: =SUMIFS(JUNHO2026!$F:$F,JUNHO2026!$Y:$Y,"Aporte para sonho")+SUMIFS(JUNHO2026!$F:$F,JUNHO2026!$D:$D,"Sonhos",JUNHO2026!$X:$X,"" ) -> 0
A8: 46204 | D8: =SUMIFS(JULHO2026!$F:$F,JULHO2026!$Y:$Y,"Investimento")+SUMIFS(JULHO2026!$F:$F,JULHO2026!$D:$D,"Investimentos",JULHO2026!$X:$X,"" ) -> 0 | E8: =SUMIFS(JULHO2026!$F:$F,JULHO2026!$Y:$Y,"Aporte para sonho")+SUMIFS(JULHO2026!$F:$F,JULHO2026!$D:$D,"Sonhos",JULHO2026!$X:$X,"" ) -> 0
A9: 46235 | D9: =SUMIFS(AGOSTO2026!$F:$F,AGOSTO2026!$Y:$Y,"Investimento")+SUMIFS(AGOSTO2026!$F:$F,AGOSTO2026!$D:$D,"Investimentos",AGOSTO2026!$X:$X,"" ) -> 250 | E9: =SUMIFS(AGOSTO2026!$F:$F,AGOSTO2026!$Y:$Y,"Aporte para sonho")+SUMIFS(AGOSTO2026!$F:$F,AGOSTO2026!$D:$D,"Sonhos",AGOSTO2026!$X:$X,"" ) -> 0
A10: 46266 | D10: =SUMIFS(SETEMBRO2026!$F:$F,SETEMBRO2026!$Y:$Y,"Investimento")+SUMIFS(SETEMBRO2026!$F:$F,SETEMBRO2026!$D:$D,"Investimentos",SETEMBRO2026!$X:$X,"" ) -> 250 | E10: =SUMIFS(SETEMBRO2026!$F:$F,SETEMBRO2026!$Y:$Y,"Aporte para sonho")+SUMIFS(SETEMBRO2026!$F:$F,SETEMBRO2026!$D:$D,"Sonhos",SETEMBRO2026!$X:$X,"" ) -> 0
A11: 46296 | D11: =SUMIFS(OUTUBRO2026!$F:$F,OUTUBRO2026!$Y:$Y,"Investimento")+SUMIFS(OUTUBRO2026!$F:$F,OUTUBRO2026!$D:$D,"Investimentos",OUTUBRO2026!$X:$X,"" ) -> 1550 | E11: =SUMIFS(OUTUBRO2026!$F:$F,OUTUBRO2026!$Y:$Y,"Aporte para sonho")+SUMIFS(OUTUBRO2026!$F:$F,OUTUBRO2026!$D:$D,"Sonhos",OUTUBRO2026!$X:$X,"" ) -> 0
A12: 46327 | D12: =SUMIFS(NOVEMBRO2026!$F:$F,NOVEMBRO2026!$Y:$Y,"Investimento")+SUMIFS(NOVEMBRO2026!$F:$F,NOVEMBRO2026!$D:$D,"Investimentos",NOVEMBRO2026!$X:$X,"" ) -> 250 | E12: =SUMIFS(NOVEMBRO2026!$F:$F,NOVEMBRO2026!$Y:$Y,"Aporte para sonho")+SUMIFS(NOVEMBRO2026!$F:$F,NOVEMBRO2026!$D:$D,"Sonhos",NOVEMBRO2026!$X:$X,"" ) -> 0
A13: 46357 | D13: =SUMIFS(DEZEMBRO2026!$F:$F,DEZEMBRO2026!$Y:$Y,"Investimento")+SUMIFS(DEZEMBRO2026!$F:$F,DEZEMBRO2026!$D:$D,"Investimentos",DEZEMBRO2026!$X:$X,"" ) -> 250 | E13: =SUMIFS(DEZEMBRO2026!$F:$F,DEZEMBRO2026!$Y:$Y,"Aporte para sonho")+SUMIFS(DEZEMBRO2026!$F:$F,DEZEMBRO2026!$D:$D,"Sonhos",DEZEMBRO2026!$X:$X,"" ) -> 0
A14: TOTAL ANUAL | B14: =SUM(B2:B13) -> 0 | C14: =SUM(C2:C13) -> 287.24 | D14: =SUM(D2:D13) -> 3996 | E14: =SUM(E2:E13) -> 100

Sheet METAS
A1: ID_META | B1: NOME | C1: VALOR_META | D1: TIPO | E1: STATUS | F1: PRIORIDADE | G1: DATA_CRIACAO | H1: DATA_FINALIZACAO
A2: M001 | B2: Relógio smart | C2: 500 | D2: ATIVA | E2: ABERTA | F2: BAIXA | G2: 46291.678
A3: M002 | B3: Teclado gamer | C3: 230 | D3: DESEJO | E3: ABERTA | F3: BAIXA | G3: 46291.678
A4: M003 | B4: Mouse gamer XQ1 Shark Pro | C4: 157 | D4: DESEJO | E4: CONCLUIDA | F4: BAIXA | G4: 46291.678 | H4: 46314.497
A5: M004 | B5: Mousepad | C5: 40 | D5: DESEJO | E5: ABERTA | F5: BAIXA | G5: 46291.678
A6: M005 | B6: Fone de ouvido com fio | C6: 20 | D6: DESEJO | E6: CONCLUIDA | F6: BAIXA | G6: 46291.678 | H6: 46291.958
A7: M006 | B7: Sapato social Democrata | C7: 200 | D7: DESEJO | E7: ABERTA | F7: ALTA | G7: 46291.678
A8: M007 | B8: Sapato Adidas casual | C8: 191 | D8: DESEJO | E8: CONCLUIDA | F8: BAIXA | G8: 46291.678
A9: M008 | B9: Sapato social Reserva | C9: 195 | D9: DESEJO | E9: ABERTA | F9: MÉDIA | G9: 46291.678
A10: M009 | B10: Camisa social | C10: 100 | D10: DESEJO | E10: ABERTA | F10: BAIXA | G10: 46291.678
A11: M010 | B11: Kit 2 Camisa polo Hering | C11: 79 | D11: DESEJO | E11: ABERTA | F11: MÉDIA | G11: 46291.678
A12: M011 | B12: Camisa polo Reserva | C12: 123 | D12: DESEJO | E12: ABERTA | F12: MÉDIA | G12: 46291.678
A13: M012 | B13: Calça social | C13: 100 | D13: DESEJO | E13: ABERTA | F13: ALTA | G13: 46291.678
A14: M013 | B14: Limpeza de dente | C14: 200 | D14: DESEJO | E14: ABERTA | F14: ALTA | G14: 46291.678
A15: M014 | B15: Capinha celular | C15: 41 | D15: DESEJO | E15: ABERTA | F15: BAIXA | G15: 46291.678
A16: M015 | B16: Película celular | C16: 34 | D16: DESEJO | E16: ABERTA | F16: BAIXA | G16: 46291.678
A17: M016 | B17: Cinto tático Invictus | C17: 259 | D17: DESEJO | E17: ABERTA | F17: ALTA | G17: 46291.678
A18: M017 | B18: 3 Blusa + 2 short de academia | C18: 111 | D18: DESEJO | E18: ABERTA | F18: BAIXA | G18: 46291.678
... A22: M021 | B22: Kit 2 jaqueta cortavento Rock Saints | C22: 81 | D22: DESEJO | E22: ABERTA | F22: BAIXA | G22: 46291.678
A23: M022 | B23: Fita para perna/coldre | C23: 30 | D23: DESEJO | E23: CONCLUIDA | F23: ALTA | G23: 46291.678 | H23: 46295.622
A24: M023 | B24: Curso de inglês Open English | C24: 2928 | D24: DESEJO | E24: ABERTA | F24: ALTA | G24: 46291.678
A25: M024 | B25: Tablet para estudo | C25: 2000 | D25: DESEJO | E25: CONCLUIDA | F25: MÉDIA | G25: 46291.678
A26: M025 | B26: Caixinha IPVA | C26: 1691.94 | D26: DESEJO | E26: ABERTA | F26: ALTA | G26: 46291.678
A27: M026 | B27: Caixinha seguro | C27: 2940 | D27: DESEJO | E27: ABERTA | F27: ALTA | G27: 46291.678
A28: M027 | B28: Capa de colete | C28: 600 | D28: DESEJO | E28: ABERTA | F28: MÉDIA | G28: 46313.308
A29: M028 | B29: Mouse gamer | C29: 99 | D29: DESEJO | E29: ABERTA | F29: MÉDIA | G29: 46314.497

Sheet INVESTIMENTOS
A1: MÊS | B1: VALOR PARA INVESTIR | E1: DATA | F1: MÊS | G1: CATEGORIA | H1: TIPO INVESTIMENTO | I1: ATIVO | J1: INSTITUIÇÃO | K1: VALOR | L1: OBSERVAÇÃO | N1: VISÃO GERAL DO MÊS
A2: 46023 | B2: =IFERROR( ABS(SUMIF(JANEIRO2026!D:D,"Investimentos",JANEIRO2026!G:G)), 0 ) -> 100 | E2: 46173 | F2: 46143 | G2: RESERVA EMERGÊNCIA | H2: CDB | I2: CDB | J2: NUBANK | K2: 1346 | N2: MÊS SELECIONADO
A3: 46054 | B3: =IFERROR( ABS(SUMIF(FEVEREIRO2026!D:D,"Investimentos",FEVEREIRO2026!G:G)), 0 ) -> 0
A4: 46082 | B4: =IFERROR( ABS(SUMIF(MARÇO2026!D:D,"Investimentos",FEVEREIRO2026!G:G)), 0 ) -> 0
A5: 46113 | B5: =IFERROR( ABS(SUMIF(ABRIL2026!D:D,"Investimentos",FEVEREIRO2026!G:G)), 0 ) -> 0 | N5: CATEGORIA | O5: VALOR INVESTIDO NO MÊS
A6: 46143 | B6: =IFERROR( ABS(SUMIF(MAIO2026!D:D,"Investimentos",FEVEREIRO2026!G:G)), 0 ) -> 0 | N6: RESERVA EMERGÊNCIA | O6: =SUMIFS( K:K, F:F, $N$3, G:G, N6 ) -> 0
A7: 46174 | B7: =IFERROR( ABS(SUMIF(JUNHO2026!D:D,"Investimentos",FEVEREIRO2026!G:G)), 0 ) -> 0 | N7: RENDA FIXA | O7: =SUMIFS( K:K, F:F, $N$3, G:G, N7 ) -> 0
A8: 46204 | B8: =IFERROR( ABS(SUMIF(JULHO2026!D:D,"Investimentos",FEVEREIRO2026!G:G)), 0 ) -> 0 | N8: FII | O8: =SUMIFS( K:K, F:F, $N$3, G:G, N8 ) -> 0
A9: 46235 | B9: =IFERROR( ABS(SUMIF(AGOSTO2026!D:D,"Investimentos",FEVEREIRO2026!G:G)), 0 ) -> 0 | N9: ETFS | O9: =SUMIFS( K:K, F:F, $N$3, G:G, N9 ) -> 0
A10: 46266 | B10: =IFERROR( ABS(SUMIF(SETEMBRO2026!D:D,"Investimentos",FEVEREIRO2026!G:G)), 0 ) -> 0 | N10: EXTERIOR | O10: =SUMIFS( K:K, F:F, $N$3, G:G, N10 ) -> 0
A11: 46296 | B11: =IFERROR( ABS(SUMIF(OUTUBRO2026!D:D,"Investimentos",FEVEREIRO2026!G:G)), 0 ) -> 0
A12: 46327 | B12: =IFERROR( ABS(SUMIF(NOVEMBRO2026!D:D,"Investimentos",FEVEREIRO2026!G:G)), 0 ) -> 0 | N12: TOTAL INVESTIDO NO MÊS | O12: =SUMIF( F:F, $N$3, K:K ) -> 0
A13: 46357 | B13: =IFERROR( ABS(SUMIF(DEZEMBRO2026!D:D,"Investimentos",FEVEREIRO2026!G:G)), 0 ) -> 0
A14: 46388
A15: 46419
A16: 46447
A17: 46478 | N17: VISSÃO TOTAL - PATRIMÔNIO | O17: VALOR TOTAL | P17: %
A18: 46508 | N18: RESERVA EMERGÊNCIA | O18: =SUMIF( G:G, N18, K:K ) -> 1346 | P18: =O18/$O$23 -> 1
A19: 46539 | N19: RENDA FIXA | O19: =SUMIF( G:G, N19, K:K ) -> 0 | P19: =O19/$O$23 -> 0
A20: 46569 | N20: FII | O20: =SUMIF( G:G, N20, K:K ) -> 0 | P20: =O20/$O$23 -> 0
A21: 46600 | N21: ETFS | O21: =SUMIF( G:G, N21, K:K ) -> 0 | P21: =O21/$O$23 -> 0
A22: 46631 | N22: EXTERIOR | O22: =SUMIF( G:G, N22, K:K ) -> 0 | P22: =O22/$O$23 -> 0
A23: 46661 | N23: TOTAL GERAL | O23: =SUM(K:K) -> 1346 | P23: =O23/$O$23 -> 1
A24: 46692
A25: 46722
A26: 46753
N27: MÊS PARA METAS
N30: VALOR PARA INVESTIR | O30: =IFERROR(VLOOKUP(N28,A:B,2,FALSE),0) -> 0
N32: CATEGORIA | O32: META (%) | P32: META (R$) | Q32: INVESTIDO | R32: DIFERENÇA | S32: PROGRESSO
N33: RESERVA EMERGÊNCIA | O33: 0.6 | P33: =O33*$O$30 -> 0 | Q33: =SUMIFS( K:K, F:F, $N$28, G:G, N33 ) -> 0 | R33: =P33-Q33 -> 0 | S33: =IF(P33>0,Q33/P33,0) -> 0
N34: RENDA FIXA | O34: 0.1 | P34: =O34*$O$30 -> 0 | Q34: =SUMIFS( K:K, F:F, $N$28, G:G, N34 ) -> 0 | R34: =P34-Q34 -> 0 | S34: =IF(P34>0,Q34/P34,0) -> 0
N35: FII | O35: 0.1 | P35: =O35*$O$30 -> 0 | Q35: =SUMIFS( K:K, F:F, $N$28, G:G, N35 ) -> 0 | R35: =P35-Q35 -> 0 | S35: =IF(P35>0,Q35/P35,0) -> 0
N36: ETFS | O36: 0.1 | P36: =O36*$O$30 -> 0 | Q36: =SUMIFS( K:K, F:F, $N$28, G:G, N36 ) -> 0 | R36: =P36-Q36 -> 0 | S36: =IF(P36>0,Q36/P36,0) -> 0
N37: EXTERIOR | O37: 0.1 | P37: =O37*$O$30 -> 0 | Q37: =SUMIFS( K:K, F:F, $N$28, G:G, N37 ) -> 0 | R37: =P37-Q37 -> 0 | S37: =IF(P37>0,Q37/P37,0) -> 0
A51: ⬇ LANÇAMENTOS MANUAIS ⬇

Sheet CATEGORIASCONFIGS
A1: TIIPOS DE LANÇAMENTO | C1: CATEGORIAS | E1: SUBCATEGORIA | H1: PLANEJAMENTO | K1: MESES | M1: FLUXO | N1: NATUREZA | O1: CATEGORIA | P1: SUBCATEGORIA | Q1: ESSENCIALIDADE | R1: COMPORTAMENTO | T1: CATEGORIA_LEGADA | U1: FLUXO | V1: NATUREZA | W1: ESSENCIALIDADE | X1: OBSERVACAO_MIGRACAO
A2: Entrada | C2: Essencial | E2: Academia | H2: CATEGORIA | I2: PERCENTUAL | K2: 45658 | M2: Entrada | N2: Receita | O2: Salário | T2: Essencial | U2: Saída | V2: Despesa | W2: Essencial | X2: A categoria de consumo original não pode ser inferida; comportamento pendente.
A3: Saída | C3: Não essencial | E3: Água | H3: ESSENCIAL | I3: 0.5 | K3: 45689 | M3: Entrada | N3: Receita | O3: Extra | T3: Não essencial | U3: Saída | V3: Despesa | W3: Não essencial | X3: A categoria de consumo original não pode ser inferida; comportamento pendente.
C4: Investimentos | E4: Cabelo | H4: Ñ ESSENCIAL | I4: 0.2 | K4: 45717 | M4: Entrada | N4: Receita | O4: Reembolso | T4: Investimentos | U4: Saída | V4: Investimento | X4: Manter natureza patrimonial; verificar categoria e subcategoria originais.
C5: Sonhos | E5: Carro | H5: INVESTIMENTO | I5: 0.3 | K5: 45748 | M5: Saída | N5: Despesa | O5: Moradia | P5: Financiamento | Q5: Essencial|Não essencial | R5: Fixo|Variável|Periódico | T5: Sonhos | U5: Saída | V5: Aporte para sonho | X5: Manter aporte separado de consumo; verificar vínculo ID_META.
C6: Salário | E6: Casamento | K6: 45778 | M6: Saída | N6: Despesa | O6: Moradia | P6: Energia | Q6: Essencial|Não essencial | R6: Fixo|Variável|Periódico | T6: Salário | U6: Entrada | V6: Receita | X6: Categoria de receita preservada.
C7: Extra | E7: Curso | K7: 45809 | M7: Saída | N7: Despesa | O7: Moradia | P7: Água | Q7: Essencial|Não essencial | R7: Fixo|Variável|Periódico | T7: Extra | U7: Entrada | V7: Receita | X7: Categoria de receita preservada.
C8: Reembolso | E8: Emergência | K8: 45839 | M8: Saída | N8: Despesa | O8: Moradia | P8: Internet | Q8: Essencial|Não essencial | R8: Fixo|Variável|Periódico | T8: Reembolso | U8: Entrada | V8: Receita | X8: Categoria de receita preservada como entrada; validar convenção do projeto.
E9: Energia | K9: 45870 | M9: Saída | N9: Despesa | O9: Moradia | P9: Condomínio | Q9: Essencial|Não essencial | R9: Fixo|Variável|Periódico
E10: Equipamento | K10: 45901 | M10: Saída | N10: Despesa | O10: Moradia | P10: Outros | Q10: Essencial|Não essencial | R10: Fixo|Variável|Periódico
E11: Estacionamento | K11: 45931 | M11: Saída | N11: Despesa | O11: Alimentação | P11: Mercado | Q11: Essencial|Não essencial | R11: Fixo|Variável|Periódico
E12: Extra | K12: 45962 | M12: Saída | N12: Despesa | O12: Alimentação | P12: Restaurante | Q12: Essencial|Não essencial | R12: Fixo|Variável|Periódico
E13: Faculdade | K13: 45992 | M13: Saída | N13: Despesa | O13: Alimentação | P13: Lanche | Q13: Essencial|Não essencial | R13: Fixo|Variável|Periódico
E14: Farmácia | K14: 46023 | M14: Saída | N14: Despesa | O14: Alimentação | P14: Delivery | Q14: Essencial|Não essencial | R14: Fixo|Variável|Periódico
E15: Gasolina | K15: 46054 | M15: Saída | N15: Despesa | O15: Alimentação | P15: Padaria | Q15: Essencial|Não essencial | R15: Fixo|Variável|Periódico
E16: Internet | K16: 46082 | M16: Saída | N16: Despesa | O16: Alimentação | P16: Outros | Q16: Essencial|Não essencial | R16: Fixo|Variável|Periódico
E17: Investimentos | K17: 46113 | M17: Saída | N17: Despesa | O17: Transporte | P17: Combustível | Q17: Essencial|Não essencial | R17: Fixo|Variável|Periódico
E18: Lanches | K18: 46143 | M18: Saída | N18: Despesa | O18: Transporte | P18: Uber | Q18: Essencial|Não essencial | R18: Fixo|Variável|Periódico
E19: Lava Jato | K19: 46174 | M19: Saída | N19: Despesa | O19: Transporte | P19: Manutenção | Q19: Essencial|Não essencial | R19: Fixo|Variável|Periódico
E20: Livro | K20: 46204 | M20: Saída | N20: Despesa | O20: Transporte | P20: Estacionamento | Q20: Essencial|Não essencial | R20: Fixo|Variável|Periódico
... E35: Viagem | K35: 46661 | M35: Saída | N35: Despesa | O35: Compras | P35: Presente | Q35: Essencial|Não essencial | R35: Fixo|Variável|Periódico
K36: 46692 | M36: Saída | N36: Despesa | O36: Compras | P36: Outros | Q36: Essencial|Não essencial | R36: Fixo|Variável|Periódico
K37: 46722 | M37: Saída | N37: Despesa | O37: Serviços | P37: Assinaturas | Q37: Essencial|Não essencial | R37: Fixo|Variável|Periódico
M38: Saída | N38: Despesa | O38: Serviços | P38: Telefonia | Q38: Essencial|Não essencial | R38: Fixo|Variável|Periódico
M39: Saída | N39: Despesa | O39: Serviços | P39: Outros | Q39: Essencial|Não essencial | R39: Fixo|Variável|Periódico
M40: Saída | N40: Despesa | O40: Pendente de classificação | P40: A classificar | Q40: Essencial|Não essencial | R40: Fixo|Variável|Periódico
M41: Saída | N41: Investimento | O41: Investimentos | P41: Renda fixa
M42: Saída | N42: Investimento | O42: Investimentos | P42: Renda variável
M43: Saída | N43: Investimento | O43: Investimentos | P43: Fundos
M44: Saída | N44: Investimento | O44: Investimentos | P44: Outros
M45: Saída | N45: Aporte para sonho | O45: Sonhos | P45: Aporte para meta

Sheet JANEIRO2026
A1: DATA | B1: TIPO | C1: DESCRIÇÃO | D1: CATEGORIA | E1: SUBCATEGORIA | F1: VALOR | G1: VALOR AJUSTADO | H1: OBSERVAÇÃO | I1: ID | J1: DASHBOARD JANEIRO | K1: VALOR | X1: FLUXO | Y1: NATUREZA | Z1: CATEGORIA_NOVA | AA1: SUBCATEGORIA_NOVA | AB1: ESSENCIALIDADE | AC1: COMPORTAMENTO | AD1: ID_MOVIMENTACAO_V2 | AE1: ID_META_V2 | AF1: STATUS_CLASSIFICACAO | AG1: PAGAMENTO_V2 | AH1: PARCELADO_V2 | AI1: QUANTIDADE_PARCELAS_V2 | AJ1: NUMERO_PARCELA_V2 | AL1: RESUMO DA CLASSIFICAÇÃO | AM1: VALOR
A2: 46023 | B2: Saída | D2: Investimentos | F2: 100 | G2: =IF(B2="Saída", -ABS(F2), ABS(F2)) -> -100 | I2: fb26de88-f953-49a8-84e8-53cc97890c3b | J2: Entrada Total | K2: =SUMIF(B:B,"Entrada",G:G) -> 0 | AL2: Receitas | AM2: =SUMIFS($F:$F,$X:$X,"Entrada",$Y:$Y,"Receita")+SUMIFS($F:$F,$B:$B,"Entrada",$X:$X,"") -> 0
A3: 46023 | B3: Saída | D3: Sonhos | F3: 100 | G3: =IF(B3="Saída", -ABS(F3), ABS(F3)) -> -100 | I3: 28c4a496-471a-42e3-b18a-2e75ccdff438 | J3: Saída Total | K3: =SUMIF(B:B,"Saída",G:G) -> -287.24 | AL3: Despesas | AM3: =SUMIFS($F:$F,$X:$X,"Saída",$Y:$Y,"Despesa")+SUMIFS($F:$F,$B:$B,"Saída",$X:$X,"",$D:$D,"<>Investimentos",$D:$D,"<>Sonhos") -> 87.24
A4: 46411.474 | B4: SAÍDA | C4: À vista | D4: Essencial | E4: Carro | F4: 43.62 | G4: =IF(B4="Saída", -ABS(F4), ABS(F4)) -> -43.62 | H4: Revisão do carro | I4: 928d1d08-43e1-4f1a-9a15-e6f46058f6cc | K4: =K2 + K3 -> -287.24 | AL4: Despesas essenciais | AM4: =SUMIFS($F:$F,$X:$X,"Saída",$Y:$Y,"Despesa",$AB:$AB,"Essencial")+SUMIFS($F:$F,$B:$B,"Saída",$X:$X,"",$D:$D,"Essencial") -> 87.24
A5: 46411.474 | B5: SAÍDA | C5: À vista | D5: Essencial | E5: Carro | F5: 43.62 | G5: =IF(B5="Saída", -ABS(F5), ABS(F5)) -> -43.62 | H5: Revisão do carro | I5: 87a617e0-2a6b-4afc-9daf-9cebbf8fbd3b | AL5: Despesas não essenciais | AM5: =SUMIFS($F:$F,$X:$X,"Saída",$Y:$Y,"Despesa",$AB:$AB,"Não essencial")+SUMIFS($F:$F,$B:$B,"Saída",$X:$X,"",$D:$D,"Não essencial") -> 0
G6: =IF(B6="Saída", -ABS(F6), ABS(F6)) -> 0 | I6: ca110051-aee4-42a0-8539-e3610955fdc6 | AL6: Investimentos | AM6: =SUMIFS($F:$F,$X:$X,"Saída",$Y:$Y,"Investimento")+SUMIFS($F:$F,$B:$B,"Saída",$X:$X,"",$D:$D,"Investimentos") -> 100
G7: =IF(B7="Saída", -ABS(F7), ABS(F7)) -> 0 | I7: 01668869-4b3c-4fc6-9be0-67608dc65976 | J7: Categoria | K7: Valor Real | M7: Categoria | N7: Valor planejado | O7: % Planejado | P7: Valor Real | Q7: Diferença | AL7: Aportes para sonhos | AM7: =SUMIFS($F:$F,$X:$X,"Saída",$Y:$Y,"Aporte para sonho")+SUMIFS($F:$F,$B:$B,"Saída",$X:$X,"",$D:$D,"Sonhos") -> 100
G8: =IF(B8="Saída", -ABS(F8), ABS(F8)) -> 0 | I8: f015517c-53b7-49e1-8dce-93b6ea79df99 | J8: Essencial | K8: =SUMIF($D:$D, J8, $F:$F) -> 87.24 | M8: Essencial | N8: =K2*O8 -> 0 | O8: 0.45 | P8: =ABS(SUMIF(D:D, M8, F:F)) -> 87.24 | Q8: =P8 - N8 -> 87.24 | AL8: Saldo financeiro | AM8: =SUMIFS($F:$F,$X:$X,"Entrada")-SUMIFS($F:$F,$X:$X,"Saída")+SUMIFS($F:$F,$B:$B,"Entrada",$X:$X,"")-SUMIFS($F:$F,$B:$B,"Saída",$X:$X,"") -> -287.24
G9: =IF(B9="Saída", -ABS(F9), ABS(F9)) -> 0 | I9: a47e1775-ee5c-4335-9b46-428b758c97e5 | J9: Não essencial | K9: =SUMIF($D:$D, J9, $F:$F) -> 0 | M9: Não essencial | N9: =K2*O9 -> 0 | O9: 0.2 | P9: =ABS(SUMIF(D:D, M9, F:F)) -> 0 | Q9: =P9 - N9 -> 0
G10: =IF(B10="Saída", -ABS(F10), ABS(F10)) -> 0 | I10: 03f582b2-a64f-4c75-804a-c752f94c41ba | J10: Investimentos | K10: =SUMIF($D:$D, J10, $F:$F) -> 100 | M10: Investimentos | N10: =K2*O10 -> 0 | O10: 0.3 | P10: =ABS(SUMIF(D:D, M10, F:F)) -> 100 | Q10: =P10 - N10 -> 100
G11: =IF(B11="Saída", -ABS(F11), ABS(F11)) -> 0 | I11: 5a6dd006-a43d-401a-9b83-30ce1d280399 | J11: Sonhos | K11: =SUMIF($D:$D, J11, $F:$F) -> 100 | M11: Sonhos | N11: =K2*O11 -> 0 | O11: 0.05 | P11: =ABS(SUMIF(D:D, M11, F:F)) -> 100 | Q11: =P11 - N11 -> 100
G12: =IF(B12="Saída", -ABS(F12), ABS(F12)) -> 0 | I12: 26d3615d-a6ca-4079-948f-8b7617573d78
G13: =IF(B13="Saída", -ABS(F13), ABS(F13)) -> 0 | I13: e82b7c58-19c7-4ef4-a8d2-02a808e07c8e
G14: =IF(B14="Saída", -ABS(F14), ABS(F14)) -> 0 | I14: acf11e76-0d60-4ffa-b138-eb388a69ebb7
G15: =IF(B15="Saída", -ABS(F15), ABS(F15)) -> 0 | I15: 2a8a34bd-5237-4dd9-b6a3-663d345719eb
G16: =IF(B16="Saída", -ABS(F16), ABS(F16)) -> 0 | I16: b6fbf558-40b2-42de-b2f2-7d7f9e91bb69
G17: =IF(B17="Saída", -ABS(F17), ABS(F17)) -> 0 | I17: d8432c62-49c9-415f-a7cc-f4f05ba5b308
G18: =IF(B18="Saída", -ABS(F18), ABS(F18)) -> 0 | I18: ebe10916-4e1f-467e-a90c-24fad3714cb3
G19: =IF(B19="Saída", -ABS(F19), ABS(F19)) -> 0 | I19: e38f2e02-1286-4d2b-a4c7-ca83bcc66f20
G20: =IF(B20="Saída", -ABS(F20), ABS(F20)) -> 0 | I20: 803e76f6-0f39-43be-91ea-de5d10b0552c
G21: =IF(B21="Saída", -ABS(F21), ABS(F21)) -> 0 | I21: 79bf1a3c-a418-43f0-beaf-852455f2b7c1
G22: =IF(B22="Saída", -ABS(F22), ABS(F22)) -> 0 | I22: d447a803-f79d-4dca-8a08-fc21f5c33328
G23: =IF(B23="Saída", -ABS(F23), ABS(F23)) -> 0 | I23: 6295bf15-851a-4d85-98f0-1ef5a3c167e7
... G50: =IF(B50="Saída", -ABS(F50), ABS(F50)) -> 0 | I50: 607e8083-665d-48d5-8a02-3bd3547e1c7d

Sheet FEVEREIRO2026
A1: DATA | B1: TIPO | C1: DESCRIÇÃO | D1: CATEGORIA | E1: SUBCATEGORIA | F1: VALOR | G1: VALOR AJUSTADO | H1: OBSERVAÇÃO | I1: ID | J1: DASHBOARD FEVEREIRO | K1: VALOR | X1: FLUXO | Y1: NATUREZA | Z1: CATEGORIA_NOVA | AA1: SUBCATEGORIA_NOVA | AB1: ESSENCIALIDADE | AC1: COMPORTAMENTO | AD1: ID_MOVIMENTACAO_V2 | AE1: ID_META_V2 | AF1: STATUS_CLASSIFICACAO | AG1: PAGAMENTO_V2 | AH1: PARCELADO_V2 | AI1: QUANTIDADE_PARCELAS_V2 | AJ1: NUMERO_PARCELA_V2 | AL1: RESUMO DA CLASSIFICAÇÃO | AM1: VALOR
A2: 46442.474 | B2: SAÍDA | C2: À vista | D2: Essencial | E2: Carro | F2: 43.62 | G2: =IF(B2="Saída",-ABS(F2),ABS(F2)) -> -43.62 | H2: Revisão do carro | I2: 84e1435b-5f82-42cc-96c9-52739d02f744 | K2: =SUMIF(B:B,"Entrada",G:G) -> 0 | AL2: Receitas | AM2: =SUMIFS($F:$F,$X:$X,"Entrada",$Y:$Y,"Receita")+SUMIFS($F:$F,$B:$B,"Entrada",$X:$X,"") -> 0
A3: 46442.474 | B3: SAÍDA | C3: À vista | D3: Essencial | E3: Carro | F3: 43.62 | G3: =IF(B3="Saída",-ABS(F3),ABS(F3)) -> -43.62 | H3: Revisão do carro | I3: e11c218c-9f2a-443d-98f8-ecd4d1f1fcda | K3: =SUMIF(B:B,"Saída",G:G) -> -87.24 | AL3: Despesas | AM3: =SUMIFS($F:$F,$X:$X,"Saída",$Y:$Y,"Despesa")+SUMIFS($F:$F,$B:$B,"Saída",$X:$X,"",$D:$D,"<>Investimentos",$D:$D,"<>Sonhos") -> 87.24
I4: d9fab454-1835-45e6-b7b2-1f3c3ae9bcfb | J4: Saldo | K4: =K2 + K3 -> -87.24 | AL4: Despesas essenciais | AM4: =SUMIFS($F:$F,$X:$X,"Saída",$Y:$Y,"Despesa",$AB:$AB,"Essencial")+SUMIFS($F:$F,$B:$B,"Saída",$X:$X,"",$D:$D,"Essencial") -> 87.24
I5: 9648a0e0-d737-44d4-85f5-d2c1b61a4334 | AL5: Despesas não essenciais | AM5: =SUMIFS($F:$F,$X:$X,"Saída",$Y:$Y,"Despesa",$AB:$AB,"Não essencial")+SUMIFS($F:$F,$B:$B,"Saída",$X:$X,"",$D:$D,"Não essencial") -> 0
I6: 02be54cf-3261-4a21-9108-f94cd9d09631 | AL6: Investimentos | AM6: =SUMIFS($F:$F,$X:$X,"Saída",$Y:$Y,"Investimento")+SUMIFS($F:$F,$B:$B,"Saída",$X:$X,"",$D:$D,"Investimentos") -> 0
I7: dce8deec-1fc1-47c6-a920-53af3d2c9a9f | J7: Categoria | K7: Valor Real | M7: Categoria | N7: Valor planejado | O7: % Planejado | P7: Valor Real | Q7: Diferença | AL7: Aportes para sonhos | AM7: =SUMIFS($F:$F,$X:$X,"Saída",$Y:$Y,"Aporte para sonho")+SUMIFS($F:$F,$B:$B,"Saída",$X:$X,"",$D:$D,"Sonhos") -> 0
I8: 7d5e3e14-f0e6-4219-b44a-35e912d5da1c | J8: Essencial | K8: =SUMIF($D:$D, J8, $F:$F) -> 87.24 | M8: Essencial | N8: =K2*O8 -> 0 | O8: 0.45 | P8: =ABS(SUMIF(D:D, M8, F:F)) -> 87.24 | Q8: =P8 - N8 -> 87.24 | AL8: Saldo financeiro | AM8: =SUMIFS($F:$F,$X:$X,"Entrada")-SUMIFS($F:$F,$X:$X,"Saída")+SUMIFS($F:$F,$B:$B,"Entrada",$X:$X,"")-SUMIFS($F:$F,$B:$B,"Saída",$X:$X,"") -> -87.24
I9: 72562636-4834-410f-b5d6-96ffef791352 | J9: Não essencial | K9: =SUMIF($D:$D, J9, $F:$F) -> 0 | M9: Não essencial | N9: =K2*O9 -> 0 | O9: 0.2 | P9: =ABS(SUMIF(D:D, M9, F:F)) -> 0 | Q9: =P9 - N9 -> 0
I10: 7b5f958d-b290-4ea9-a7bd-3a504f84d9c9 | J10: Investimentos | K10: =SUMIF($D:$D, J10, $F:$F) -> 0 | M10: Investimentos | N10: =K2*O10 -> 0 | O10: 0.3 | P10: =ABS(SUMIF(D:D, M10, F:F)) -> 0 | Q10: =P10 - N10 -> 0
I11: c4e2b1d7-3046-4bdc-bbaf-dc577f055dd8 | J11: Sonhos | K11: =SUMIF($D:$D, J11, $F:$F) -> 0 | M11: Sonhos | N11: =K2*O11 -> 0 | O11: 0.05 | P11: =ABS(SUMIF(D:D, M11, F:F)) -> 0 | Q11: =P11 - N11 -> 0
I12: 74450ae5-7382-47e3-9f53-7e962b306acf
I13: 186513bb-24f4-495f-800c-3021cf1e69ee
I14: 12480e0f-9e26-4bef-9ec1-2df0beeb8efc
I15: 7d7e5c74-0f7d-4927-98ad-85644785c30e
I16: da5ff42e-9f22-4e96-b787-00e8ba4049c4
I17: be2946db-4f9d-4deb-a891-b8f863cf73e4
I18: 10783252-01f0-486c-9365-de71d1f87ab0
I19: 9bcff795-370a-4032-bad6-7557d2fe354d
I20: c0f9bb80-4ea1-4494-a9ef-9b31e52c3176
I21: 6cf306a8-ccdb-4dce-ab0c-5e2faefd6b64
I22: c0c6e168-55b3-4048-8bce-dcf971a427bd
I23: 18dee03f-ecfd-41b8-940c-43938e5f51d2
... I38: 252c515a-1676-4727-9f97-3d74f438f257
G39: =IF(B39="Saída", -ABS(F39), ABS(F39)) -> 0 | I39: f2955499-9f3c-4b73-994d-0271a9a6352d
G40: =IF(B40="Saída", -ABS(F40), ABS(F40)) -> 0 | I40: 9630b0ca-910b-414a-a3df-0d8ed6cceacb
G41: =IF(B41="Saída", -ABS(F41), ABS(F41)) -> 0 | I41: 4386111c-83aa-4a7a-a412-4c8f6b920860
G42: =IF(B42="Saída", -ABS(F42), ABS(F42)) -> 0 | I42: c21321c5-525c-49cd-8288-a7c085cebbd2
G43: =IF(B43="Saída", -ABS(F43), ABS(F43)) -> 0 | I43: 10d78826-f677-4a01-8976-38e056a8dc40
G44: =IF(B44="Saída", -ABS(F44), ABS(F44)) -> 0 | I44: c247cfd1-2127-4507-b848-be701b674fd3
G45: =IF(B45="Saída", -ABS(F45), ABS(F45)) -> 0 | I45: a6cc2711-9e06-4e3e-baea-8187c0b88f8f
G46: =IF(B46="Saída", -ABS(F46), ABS(F46)) -> 0 | I46: 9a2d6665-b023-4743-a8e6-c35fcd51a0a0
G47: =IF(B47="Saída", -ABS(F47), ABS(F47)) -> 0 | I47: b08f82ba-e390-4a23-8d8c-c52c4ee46759
G48: =IF(B48="Saída", -ABS(F48), ABS(F48)) -> 0 | I48: af8d4211-941b-4699-a7fe-4c4fe30297c7
G49: =IF(B49="Saída", -ABS(F49), ABS(F49)) -> 0 | I49: d46153fb-accd-42a0-80a4-fe578a6fdb42
G50: =IF(B50="Saída", -ABS(F50), ABS(F50)) -> 0 | I50: 19c52e22-1c19-469a-b5ec-09416f666f15

Sheet MARÇO2026
A1: DATA | B1: TIPO | C1: DESCRIÇÃO | D1: CATEGORIA | E1: SUBCATEGORIA | F1: VALOR | G1: VALOR AJUSTADO | H1: OBSERVAÇÃO | I1: ID | J1: DASHBOARD JANEIRO | K1: VALOR | X1: FLUXO | Y1: NATUREZA | Z1: CATEGORIA_NOVA | AA1: SUBCATEGORIA_NOVA | AB1: ESSENCIALIDADE | AC1: COMPORTAMENTO | AD1: ID_MOVIMENTACAO_V2 | AE1: ID_META_V2 | AF1: STATUS_CLASSIFICACAO | AG1: PAGAMENTO_V2 | AH1: PARCELADO_V2 | AI1: QUANTIDADE_PARCELAS_V2 | AJ1: NUMERO_PARCELA_V2 | AL1: RESUMO DA CLASSIFICAÇÃO | AM1: VALOR
A2: 46470.474 | B2: SAÍDA | C2: À vista | D2: Essencial | E2: Carro | F2: 43.6 | G2: =IF(B2="Saída", -ABS(F2), ABS(F2)) -> -43.6 | H2: Revisão do carro | I2: aef2dd05-aa86-46cc-bd71-d361caccd8bc | K2: =SUMIF(B:B,"Entrada",G:G) -> 0 | AL2: Receitas | AM2: =SUMIFS($F:$F,$X:$X,"Entrada",$Y:$Y,"Receita")+SUMIFS($F:$F,$B:$B,"Entrada",$X:$X,"") -> 0
A3: 46470.474 | B3: SAÍDA | C3: À vista | D3: Essencial | E3: Carro | F3: 43.6 | G3: =IF(B3="Saída", -ABS(F3), ABS(F3)) -> -43.6 | H3: Revisão do carro | I3: 06b050b7-dda2-4a45-a8a2-a5d4559f3857 | K3: =SUMIF(B:B,"Saída",G:G) -> -87.2 | AL3: Despesas | AM3: =SUMIFS($F:$F,$X:$X,"Saída",$Y:$Y,"Despesa")+SUMIFS($F:$F,$B:$B,"Saída",$X:$X,"",$D:$D,"<>Investimentos",$D:$D,"<>Sonhos") -> 87.2
G4: =IF(B4="Saída", -ABS(F4), ABS(F4)) -> 0 | I4: 08bba41a-5299-4c2d-82bd-3b1f1b3899f0 | J4: Saldo | K4: =K2 + K3 -> -87.2 | AL4: Despesas essenciais | AM4: =SUMIFS($F:$F,$X:$X,"Saída",$Y:$Y,"Despesa",$AB:$AB,"Essencial")+SUMIFS($F:$F,$B:$B,"Saída",$X:$X,"",$D:$D,"Essencial") -> 87.2
G5: =IF(B5="Saída", -ABS(F5), ABS(F5)) -> 0 | I5: 6230709a-8c18-41c8-af9e-ab5a4ed1f714 | AL5: Despesas não essenciais | AM5: =SUMIFS($F:$F,$X:$X,"Saída",$Y:$Y,"Despesa",$AB:$AB,"Não essencial")+SUMIFS($F:$F,$B:$B,"Saída",$X:$X,"",$D:$D,"Não essencial") -> 0
G6: =IF(B6="Saída", -ABS(F6), ABS(F6)) -> 0 | I6: 608a3fd2-4d3c-4077-9525-380da3b0c0c0 | AL6: Investimentos | AM6: =SUMIFS($F:$F,$X:$X,"Saída",$Y:$Y,"Investimento")+SUMIFS($F:$F,$B:$B,"Saída",$X:$X,"",$D:$D,"Investimentos") -> 0
G7: =IF(B7="Saída", -ABS(F7), ABS(F7)) -> 0 | I7: 347dc22d-50a9-4ca5-a9c3-99f65e278e36 | J7: Categoria | K7: Valor Real | M7: Categoria | N7: Valor planejado | O7: % Planejado | P7: Valor Real | Q7: Diferença | AL7: Aportes para sonhos | AM7: =SUMIFS($F:$F,$X:$X,"Saída",$Y:$Y,"Aporte para sonho")+SUMIFS($F:$F,$B:$B,"Saída",$X:$X,"",$D:$D,"Sonhos") -> 0
G8: =IF(B8="Saída", -ABS(F8), ABS(F8)) -> 0 | I8: eec7c5a3-54ef-48a2-b774-9c9189180a93 | J8: Essencial | K8: =SUMIF($D:$D, J8, $F:$F) -> 87.2 | M8: Essencial | N8: =K2*O8 -> 0 | O8: 0.45 | P8: =ABS(SUMIF(D:D, M8, F:F)) -> 87.2 | Q8: =P8 - N8 -> 87.2 | AL8: Saldo financeiro | AM8: =SUMIFS($F:$F,$X:$X,"Entrada")-SUMIFS($F:$F,$X:$X,"Saída")+SUMIFS($F:$F,$B:$B,"Entrada",$X:$X,"")-SUMIFS($F:$F,$B:$B,"Saída",$X:$X,"") -> -87.2
G9: =IF(B9="Saída", -ABS(F9), ABS(F9)) -> 0 | I9: 38b4060c-2084-4f51-96e9-4a839880f134 | J9: Não essencial | K9: =SUMIF($D:$D, J9, $F:$F) -> 0 | M9: Não essencial | N9: =K2*O9 -> 0 | O9: 0.2 | P9: =ABS(SUMIF(D:D, M9, F:F)) -> 0 | Q9: =P9 - N9 -> 0
G10: =IF(B10="Saída", -ABS(F10), ABS(F10)) -> 0 | I10: e3e34366-e469-45ec-9e24-a54daf760230 | J10: Investimentos | K10: =SUMIF($D:$D, J10, $F:$F) -> 0 | M10: Investimentos | N10: =K2*O10 -> 0 | O10: 0.3 | P10: =ABS(SUMIF(D:D, M10, F:F)) -> 0 | Q10: =P10 - N10 -> 0
G11: =IF(B11="Saída", -ABS(F11), ABS(F11)) -> 0 | I11: 78621a7f-2cef-4f64-afa8-cda1416ec1ff | J11: Sonhos | K11: =SUMIF($D:$D, J11, $F:$F) -> 0 | M11: Sonhos | N11: =K2*O11 -> 0 | O11: 0.05 | P11: =ABS(SUMIF(D:D, M11, F:F)) -> 0 | Q11: =P11 - N11 -> 0
G12: =IF(B12="Saída", -ABS(F12), ABS(F12)) -> 0 | I12: 3050afba-5146-443c-a512-d262db7a669e
G13: =IF(B13="Saída", -ABS(F13), ABS(F13)) -> 0 | I13: 93c47547-6b19-4c49-8cc7-03ee48a0ea64
G14: =IF(B14="Saída", -ABS(F14), ABS(F14)) -> 0 | I14: 755f743e-e564-423c-9923-d3115a007167
G15: =IF(B15="Saída", -ABS(F15), ABS(F15)) -> 0 | I15: 686b4ca3-8f35-4e9d-b8a2-55c5e08f5743
G16: =IF(B16="Saída", -ABS(F16), ABS(F16)) -> 0 | I16: d2cf9c60-a563-49d1-9382-fcd66f70d6a1
G17: =IF(B17="Saída", -ABS(F17), ABS(F17)) -> 0 | I17: 02fac534-2bc0-43c8-abe9-9dc4e8d50992
G18: =IF(B18="Saída", -ABS(F18), ABS(F18)) -> 0 | I18: 41747cc2-b6ca-4067-b5d6-e08c027fb797
G19: =IF(B19="Saída", -ABS(F19), ABS(F19)) -> 0 | I19: ac23d7ce-361f-4cd3-b397-426e05fd200b
G20: =IF(B20="Saída", -ABS(F20), ABS(F20)) -> 0 | I20: 1d6e0eab-4afc-4307-aae5-aa1284563c79
G21: =IF(B21="Saída", -ABS(F21), ABS(F21)) -> 0 | I21: 5a8314f7-478d-4aa6-a33b-46199cc4f117
G22: =IF(B22="Saída", -ABS(F22), ABS(F22)) -> 0 | I22: 524f5a3f-be16-4093-9601-530fa1ef17cf
G23: =IF(B23="Saída", -ABS(F23), ABS(F23)) -> 0 | I23: f2f666ab-fd66-43da-a606-d121feee548d
... G50: =IF(B50="Saída", -ABS(F50), ABS(F50)) -> 0 | I50: 274afaac-ab8b-4458-95ec-cb1116c9ab88

Sheet ABRIL2026
A1: DATA | B1: TIPO | C1: DESCRIÇÃO | D1: CATEGORIA | E1: SUBCATEGORIA | F1: VALOR | G1: VALOR AJUSTADO | H1: OBSERVAÇÃO | I1: ID | J1: DASHBOARD JANEIRO | K1: VALOR | X1: FLUXO | Y1: NATUREZA | Z1: CATEGORIA_NOVA | AA1: SUBCATEGORIA_NOVA | AB1: ESSENCIALIDADE | AC1: COMPORTAMENTO | AD1: ID_MOVIMENTACAO_V2 | AE1: ID_META_V2 | AF1: STATUS_CLASSIFICACAO | AG1: PAGAMENTO_V2 | AH1: PARCELADO_V2 | AI1: QUANTIDADE_PARCELAS_V2 | AJ1: NUMERO_PARCELA_V2 | AL1: RESUMO DA CLASSIFICAÇÃO | AM1: VALOR
G2: =IF(B2="Saída", -ABS(F2), ABS(F2)) -> 0 | I2: ee051166-f9ad-4d2e-a741-0de77dada154 | J2: Entrada Total | K2: =SUMIF(B:B,"Entrada",G:G) -> 0 | AL2: Receitas | AM2: =SUMIFS($F:$F,$X:$X,"Entrada",$Y:$Y,"Receita")+SUMIFS($F:$F,$B:$B,"Entrada",$X:$X,"") -> 0
G3: =IF(B3="Saída", -ABS(F3), ABS(F3)) -> 0 | I3: a52eabe3-053b-46e6-838e-8b4a99ffca5d | J3: Saída Total | K3: =SUMIF(B:B,"Saída",G:G) -> 0 | AL3: Despesas | AM3: =SUMIFS($F:$F,$X:$X,"Saída",$Y:$Y,"Despesa")+SUMIFS($F:$F,$B:$B,"Saída",$X:$X,"",$D:$D,"<>Investimentos",$D:$D,"<>Sonhos") -> 0
G4: =IF(B4="Saída", -ABS(F4), ABS(F4)) -> 0 | I4: 9cd0c19a-23d9-4fc2-966e-b51ae3fe3723 | J4: Saldo | K4: =K2 + K3 -> 0 | AL4: Despesas essenciais | AM4: =SUMIFS($F:$F,$X:$X,"Saída",$Y:$Y,"Despesa",$AB:$AB,"Essencial")+SUMIFS($F:$F,$B:$B,"Saída",$X:$X,"",$D:$D,"Essencial") -> 0
G5: =IF(B5="Saída", -ABS(F5), ABS(F5)) -> 0 | I5: 5d93ddf7-361a-4788-a9e5-6e300c7ac6c6 | AL5: Despesas não essenciais | AM5: =SUMIFS($F:$F,$X:$X,"Saída",$Y:$Y,"Despesa",$AB:$AB,"Não essencial")+SUMIFS($F:$F,$B:$B,"Saída",$X:$X,"",$D:$D,"Não essencial") -> 0
G6: =IF(B6="Saída", -ABS(F6), ABS(F6)) -> 0 | I6: cba7f8bb-1d74-4f27-9e0f-ad7aa1d21166 | AL6: Investimentos | AM6: =SUMIFS($F:$F,$X:$X,"Saída",$Y:$Y,"Investimento")+SUMIFS($F:$F,$B:$B,"Saída",$X:$X,"",$D:$D,"Investimentos") -> 0
G7: =IF(B7="Saída", -ABS(F7), ABS(F7)) -> 0 | I7: e128d244-20b5-49ca-8f77-44778cf90c6c | J7: Categoria | K7: Valor Real | M7: Categoria | N7: Valor planejado | O7: % Planejado | P7: Valor Real | Q7: Diferença | AL7: Aportes para sonhos | AM7: =SUMIFS($F:$F,$X:$X,"Saída",$Y:$Y,"Aporte para sonho")+SUMIFS($F:$F,$B:$B,"Saída",$X:$X,"",$D:$D,"Sonhos") -> 0
G8: =IF(B8="Saída", -ABS(F8), ABS(F8)) -> 0 | I8: 9897b07f-7354-450d-846e-c41f78c59589 | J8: Essencial | K8: =SUMIF($D:$D, J8, $F:$F) -> 0 | M8: Essencial | N8: =K2*O8 -> 0 | O8: 0.45 | P8: =ABS(SUMIF(D:D, M8, F:F)) -> 0 | Q8: =P8 - N8 -> 0 | AL8: Saldo financeiro | AM8: =SUMIFS($F:$F,$X:$X,"Entrada")-SUMIFS($F:$F,$X:$X,"Saída")+SUMIFS($F:$F,$B:$B,"Entrada",$X:$X,"")-SUMIFS($F:$F,$B:$B,"Saída",$X:$X,"") -> 0
G9: =IF(B9="Saída", -ABS(F9), ABS(F9)) -> 0 | I9: 99c56ab5-6039-4ebc-b599-d95f7eb7bced | J9: Não essencial | K9: =SUMIF($D:$D, J9, $F:$F) -> 0 | M9: Não essencial | N9: =K2*O9 -> 0 | O9: 0.2 | P9: =ABS(SUMIF(D:D, M9, F:F)) -> 0 | Q9: =P9 - N9 -> 0
G10: =IF(B10="Saída", -ABS(F10), ABS(F10)) -> 0 | I10: 4bdb8fd5-19ae-4661-92fa-61ac56730d51 | J10: Investimentos | K10: =SUMIF($D:$D, J10, $F:$F) -> 0 | M10: Investimentos | N10: =K2*O10 -> 0 | O10: 0.3 | P10: =ABS(SUMIF(D:D, M10, F:F)) -> 0 | Q10: =P10 - N10 -> 0
G11: =IF(B11="Saída", -ABS(F11), ABS(F11)) -> 0 | I11: e03682c8-58d3-43e2-97cb-894c73f477c2 | J11: Sonhos | K11: =SUMIF($D:$D, J11, $F:$F) -> 0 | M11: Sonhos | N11: =K2*O11 -> 0 | O11: 0.05 | P11: =ABS(SUMIF(D:D, M11, F:F)) -> 0 | Q11: =P11 - N11 -> 0
G12: =IF(B12="Saída", -ABS(F12), ABS(F12)) -> 0 | I12: 51dbc27b-d297-4e06-8223-be5952c9b4f4
G13: =IF(B13="Saída", -ABS(F13), ABS(F13)) -> 0 | I13: 3b26d293-7e56-4105-bf90-51e74f246850
G14: =IF(B14="Saída", -ABS(F14), ABS(F14)) -> 0 | I14: 3cb9e4f9-5e89-44e4-87a1-022c77c0a3da
G15: =IF(B15="Saída", -ABS(F15), ABS(F15)) -> 0 | I15: bd9cfc89-21b8-45d7-b5ed-728806386c19
G16: =IF(B16="Saída", -ABS(F16), ABS(F16)) -> 0 | I16: 08919c57-ef95-4cca-b77e-71d47706610b
G17: =IF(B17="Saída", -ABS(F17), ABS(F17)) -> 0 | I17: 5dae4c73-6de1-46bd-a5e1-f91f449c88aa
G18: =IF(B18="Saída", -ABS(F18), ABS(F18)) -> 0 | I18: 7a96a2b5-70b1-42a7-9961-ecd7ea74004d
G19: =IF(B19="Saída", -ABS(F19), ABS(F19)) -> 0 | I19: 3ddfa8ed-f2a6-4aac-bb05-b374a0d48aca
G20: =IF(B20="Saída", -ABS(F20), ABS(F20)) -> 0 | I20: 36d61550-9ec9-442b-bdff-df3c5eb04998
G21: =IF(B21="Saída", -ABS(F21), ABS(F21)) -> 0 | I21: 7559ff80-9062-4ce6-83d5-348643f82749
G22: =IF(B22="Saída", -ABS(F22), ABS(F22)) -> 0 | I22: 1f45851b-c152-49f2-9b7d-603156fb4740
G23: =IF(B23="Saída", -ABS(F23), ABS(F23)) -> 0 | I23: b1b62a36-584c-49a4-8b04-f9b6185607d0
... G50: =IF(B50="Saída", -ABS(F50), ABS(F50)) -> 0 | I50: e2059229-4675-4e8f-84e0-7c9eb5eb661e

Sheet MAIO2026
A1: DATA | B1: TIPO | C1: DESCRIÇÃO | D1: CATEGORIA | E1: SUBCATEGORIA | F1: VALOR | G1: VALOR AJUSTADO | H1: OBSERVAÇÃO | I1: ID | J1: DASHBOARD JANEIRO | K1: VALOR | X1: FLUXO | Y1: NATUREZA | Z1: CATEGORIA_NOVA | AA1: SUBCATEGORIA_NOVA | AB1: ESSENCIALIDADE | AC1: COMPORTAMENTO | AD1: ID_MOVIMENTACAO_V2 | AE1: ID_META_V2 | AF1: STATUS_CLASSIFICACAO | AG1: PAGAMENTO_V2 | AH1: PARCELADO_V2 | AI1: QUANTIDADE_PARCELAS_V2 | AJ1: NUMERO_PARCELA_V2 | AL1: RESUMO DA CLASSIFICAÇÃO | AM1: VALOR
A2: 46143 | B2: Saída | D2: Essencial | E2: Manutenção carro | F2: 126.66 | G2: =IF(B2="Saída", -ABS(F2), ABS(F2)) -> -126.66 | H2: revisão carro | I2: 6a66c4eb-b210-41b3-bc36-d8db5d559ad4 | J2: Entrada Total | K2: =SUMIF(B:B,"Entrada",G:G) -> 7076 | AL2: Receitas | AM2: =SUMIFS($F:$F,$X:$X,"Entrada",$Y:$Y,"Receita")+SUMIFS($F:$F,$B:$B,"Entrada",$X:$X,"") -> 7076
A3: 46143 | B3: Saída | D3: Essencial | E3: Mercado | F3: 35 | G3: =IF(B3="Saída", -ABS(F3), ABS(F3)) -> -35 | H3: almoço | I3: e179cefb-b21e-42d6-89f9-e2036c634a42 | J3: Saída Total | K3: =SUMIF(B:B,"Saída",G:G) -> -7070.95 | AL3: Despesas | AM3: =SUMIFS($F:$F,$X:$X,"Saída",$Y:$Y,"Despesa")+SUMIFS($F:$F,$B:$B,"Saída",$X:$X,"",$D:$D,"<>Investimentos",$D:$D,"<>Sonhos") -> 5724.95
A4: 46143 | B4: Saída | D4: Essencial | E4: Emergência | F4: 26 | G4: =IF(B4="Saída", -ABS(F4), ABS(F4)) -> -26 | H4: farmácia | I4: 531d5f20-2c32-4fb8-bcbd-cca6b5c401bd | J4: Saldo | K4: =K2 + K3 -> 5.05 | AL4: Despesas essenciais | AM4: =SUMIFS($F:$F,$X:$X,"Saída",$Y:$Y,"Despesa",$AB:$AB,"Essencial")+SUMIFS($F:$F,$B:$B,"Saída",$X:$X,"",$D:$D,"Essencial") -> 5142.58
A5: 46143 | B5: Saída | D5: Não essencial | E5: Lanches | F5: 71.7 | G5: =IF(B5="Saída", -ABS(F5), ABS(F5)) -> -71.7 | H5: lanche subway avós | I5: 45dafa09-635e-4202-b223-be5493294ae8 | AL5: Despesas não essenciais | AM5: =SUMIFS($F:$F,$X:$X,"Saída",$Y:$Y,"Despesa",$AB:$AB,"Não essencial")+SUMIFS($F:$F,$B:$B,"Saída",$X:$X,"",$D:$D,"Não essencial") -> 582.37
A6: 46144 | B6: Saída | D6: Essencial | E6: Lanches | F6: 42.7 | G6: =IF(B6="Saída", -ABS(F6), ABS(F6)) -> -42.7 | H6: lanche serviço | I6: 92822d01-d1e3-4c22-b9e3-cd9357b624e5 | AL6: Investimentos | AM6: =SUMIFS($F:$F,$X:$X,"Saída",$Y:$Y,"Investimento")+SUMIFS($F:$F,$B:$B,"Saída",$X:$X,"",$D:$D,"Investimentos") -> 1346
A7: 46145 | B7: Saída | D7: Essencial | E7: Lanches | F7: 72.6 | G7: =IF(B7="Saída", -ABS(F7), ABS(F7)) -> -72.6 | H7: almoço gabi | I7: ae96bf21-f900-403b-8747-c7f078c218a3 | J7: Categoria | K7: Valor Real | M7: Categoria | N7: Valor planejado | O7: % Planejado | P7: Valor Real | Q7: Diferença | AL7: Aportes para sonhos | AM7: =SUMIFS($F:$F,$X:$X,"Saída",$Y:$Y,"Aporte para sonho")+SUMIFS($F:$F,$B:$B,"Saída",$X:$X,"",$D:$D,"Sonhos") -> 0
A8: 46145 | B8: Saída | D8: Não essencial | E8: Lanches | F8: 23.98 | G8: =IF(B8="Saída", -ABS(F8), ABS(F8)) -> -23.98 | H8: sobremesa gabi | I8: 0084d33a-7600-4451-b349-82b197624f9d | J8: Essencial | K8: =SUMIF($D:$D, J8, $F:$F) -> 5142.58 | M8: Essencial | N8: =K2*O8 -> 3184.2 | O8: 0.45 | P8: =ABS(SUMIF(D:D, M8, F:F)) -> 5142.58 | Q8: =P8 - N8 -> 1958.38 | AL8: Saldo financeiro | AM8: =SUMIFS($F:$F,$X:$X,"Entrada")-SUMIFS($F:$F,$X:$X,"Saída")+SUMIFS($F:$F,$B:$B,"Entrada",$X:$X,"")-SUMIFS($F:$F,$B:$B,"Saída",$X:$X,"") -> 5.05
A9: 46145 | B9: Saída | D9: Não essencial | E9: Lanches | F9: 78.8 | G9: =IF(B9="Saída", -ABS(F9), ABS(F9)) -> -78.8 | H9: lanche pós culto | I9: fc1af8d9-79ea-4da4-9135-2f058ce5982e | J9: Não essencial | K9: =SUMIF($D:$D, J9, $F:$F) -> 582.37 | M9: Não essencial | N9: =K2*O9 -> 1415.2 | O9: 0.2 | P9: =ABS(SUMIF(D:D, M9, F:F)) -> 582.37 | Q9: =P9 - N9 -> -832.83
A10: 46146 | B10: Saída | D10: Essencial | E10: Lanches | F10: 20 | G10: =IF(B10="Saída", -ABS(F10), ABS(F10)) -> -20 | H10: almoço | I10: d7e425b0-4564-48d5-bc8c-d6f65adb13e5 | J10: Investimentos | K10: =SUMIF($D:$D, J10, $F:$F) -> 1346 | M10: Investimentos | N10: =K2*O10 -> 2122.8 | O10: 0.3 | P10: =ABS(SUMIF(D:D, M10, F:F)) -> 1346 | Q10: =P10 - N10 -> -776.8
A11: 46147 | B11: Saída | D11: Essencial | E11: Lanches | F11: 20 | G11: =IF(B11="Saída", -ABS(F11), ABS(F11)) -> -20 | H11: almoço | I11: e883b2de-1d07-4013-8459-fa8a2a927ff5 | J11: Sonhos | K11: =SUMIF($D:$D, J11, $F:$F) -> 0 | M11: Sonhos | N11: =K2*O11 -> 353.8 | O11: 0.05 | P11: =ABS(SUMIF(D:D, M11, F:F)) -> 0 | Q11: =P11 - N11 -> -353.8
A12: 46147 | B12: Saída | D12: Essencial | E12: Lanches | F12: 14 | G12: =IF(B12="Saída", -ABS(F12), ABS(F12)) -> -14 | H12: ovo | I12: d7db0af8-69a3-4d22-812a-155d921b5a97
A13: 46147 | B13: Saída | D13: Não essencial | E13: Lanches | F13: 67.9 | G13: =IF(B13="Saída", -ABS(F13), ABS(F13)) -> -67.9 | H13: lanche subway murilo | I13: 07d9c843-829c-47ee-b4c5-880493bfa912
A14: 46148 | B14: Saída | D14: Essencial | E14: Lanches | F14: 20 | G14: =IF(B14="Saída", -ABS(F14), ABS(F14)) -> -20 | H14: almoço | I14: 5d97258c-7abf-4b39-ab45-eb0e59305209
A15: 46148 | B15: Saída | D15: Essencial | E15: Moradia | F15: 200 | G15: =IF(B15="Saída", -ABS(F15), ABS(F15)) -> -200 | H15: compras avós | I15: d7d15243-e43a-4453-87d2-113812ef0532
A16: 46143 | B16: Saída | D16: Essencial | E16: Curso | F16: 24.9 | G16: =IF(B16="Saída", -ABS(F16), ABS(F16)) -> -24.9 | H16: plano qc | I16: 685ff265-b028-4ba5-aae2-cd7b0fb82a08
A17: 46143 | B17: Saída | D17: Essencial | E17: Emergência | F17: 399.9 | G17: =IF(B17="Saída", -ABS(F17), ABS(F17)) -> -399.9 | H17: celular | I17: 4b06a470-7b8e-4baf-9ccd-9ef13935f234
A18: 46143 | B18: Saída | D18: Essencial | F18: 294.32 | G18: =IF(B18="Saída", -ABS(F18), ABS(F18)) -> -294.32 | H18: seguro | I18: 1bf55abb-8ede-49bc-a7ad-d08b33bb4537
A19: 46143 | B19: Saída | D19: Essencial | F19: 1500 | G19: =IF(B19="Saída", -ABS(F19), ABS(F19)) -> -1500 | H19: carro | I19: c352a022-4e81-446b-9b7c-924ae4e79886
A20: 46143 | B20: Saída | D20: Essencial | F20: 707.68 | G20: =IF(B20="Saída", -ABS(F20), ABS(F20)) -> -707.68 | H20: dízimo | I20: 755fc2a9-b01b-498e-b095-43d8fef9745d
A21: 46143 | B21: Saída | D21: Essencial | F21: 60 | G21: =IF(B21="Saída", -ABS(F21), ABS(F21)) -> -60 | H21: grêmio | I21: cc686659-e6d3-4f34-80d2-825addfd306d
A22: 46143 | B22: Saída | D22: Essencial | F22: 281.99 | G22: =IF(B22="Saída", -ABS(F22), ABS(F22)) -> -281.99 | H22: ipva | I22: cd15cc86-49dc-4c43-a762-cb1cfbb10f8c
A23: 46143 | B23: Saída | D23: Essencial | F23: 250 | G23: =IF(B23="Saída", -ABS(F23), ABS(F23)) -> -250 | H23: casamento | I23: d2224915-37a3-4252-8255-8a726ce4bfd5
A24: 46143 | B24: Saída | D24: Essencial | F24: 380.22 | G24: =IF(B24="Saída", -ABS(F24), ABS(F24)) -> -380.22 | H24: formatura | I24: dd69c1cb-f2c1-4267-981a-c10d7e8ad00b
A25: 46149 | B25: Saída | D25: Não essencial | E25: Lanches | F25: 8 | G25: =IF(B25="Saída", -ABS(F25), ABS(F25)) -> -8 | H25: din din | I25: 267e8e85-1e0c-4590-aad1-14879cbd864c
A26: 46150 | B26: Saída | D26: Essencial | E26: Lanches | F26: 212 | G26: =IF(B26="Saída", -ABS(F26), ABS(F26)) -> -212 | H26: almoço | I26: 259db16a-b6bc-492b-9177-1aa300c642d6
A27: 46150 | B27: Saída | D27: Essencial | E27: Lanches | F27: 20 | G27: =IF(B27="Saída", -ABS(F27), ABS(F27)) -> -20 | H27: jantar do serviço de sábado | I27: f88fca8c-c5fb-457f-8f39-b4066ea1c61e
A28: 46153 | B28: Saída | D28: Não essencial | F28: 12 | G28: =IF(B28="Saída", -ABS(F28), ABS(F28)) -> -12 | H28: impressão tco | I28: e9313d3c-e918-4f30-8aaa-8f1f3905fe05
A29: 46155 | B29: Saída | D29: Não essencial | E29: Lanches | F29: 43 | G29: =IF(B29="Saída", -ABS(F29), ABS(F29)) -> -43 | H29: caldo maumau | I29: 0066d352-0f85-4991-bbd2-9e13ae3aff19
A30: 46156 | B30: Saída | D30: Essencial | E30: Gasolina | F30: 220 | G30: =IF(B30="Saída", -ABS(F30), ABS(F30)) -> -220 | H30: gasolina(pix) | I30: 187a47d0-1068-48c3-a189-d8a44cbcfd51
A31: 46157 | B31: Saída | D31: Essencial | E31: Mercado | F31: 22 | G31: =IF(B31="Saída", -ABS(F31), ABS(F31)) -> -22 | H31: pão para os lanches | I31: 5b14a6c6-83e9-46f5-9db7-7248f43b26e3
A32: 46157 | B32: Saída | D32: Essencial | E32: Mercado | F32: 59.72 | G32: =IF(B32="Saída", -ABS(F32), ABS(F32)) -> -59.72 | H32: carne p/ chácara | I32: a287f22f-eb1d-4131-8595-3f7afdeed7cc
A33: 46157 | B33: Saída | D33: Não essencial | E33: Mercado | F33: 5 | G33: =IF(B33="Saída", -ABS(F33), ABS(F33)) -> -5 | H33: band-aid; tia | I33: 03c7de4f-aafb-4de8-8a82-4b9844c0dc79
A34: 46159 | B34: Saída | D34: Essencial | E34: Restaurante | F34: 32.4 | G34: =IF(B34="Saída", -ABS(F34), ABS(F34)) -> -32.4 | H34: almoço no serviço | I34: e44f112c-4bc2-49cf-a856-4882603ecb30
A35: 46164 | B35: Saída | D35: Não essencial | E35: Lanches | F35: 19.99 | G35: =IF(B35="Saída", -ABS(F35), ABS(F35)) -> -19.99 | H35: jantar com gabi | I35: 99e71aff-cf33-4ff0-98a8-135be386bf62
A36: 46164 | B36: Saída | D36: Não essencial | E36: Lanches | F36: 71 | G36: =IF(B36="Saída", -ABS(F36), ABS(F36)) -> -71 | H36: jantar com gabi | I36: 78db9da0-3b83-4d97-a7e3-d4312a5f782c
A37: 46165 | B37: Saída | D37: Essencial | E37: Lanches | F37: 35.5 | G37: =IF(B37="Saída", -ABS(F37), ABS(F37)) -> -35.5 | H37: lanche pós culto | I37: c6ae1ed6-a695-44a0-b94b-da6440d9fe64
A38: 46166 | B38: Saída | D38: Não essencial | E38: Uber | F38: 23.94 | G38: =IF(B38="Saída", -ABS(F38), ABS(F38)) -> -23.94 | H38: uber avô | I38: 24d0d9c8-f4a6-48f1-ae6b-3c088c211503
A39: 46166 | B39: Saída | D39: Não essencial | E39: Lanches | F39: 9 | G39: =IF(B39="Saída", -ABS(F39), ABS(F39)) -> -9 | H39: h2o almoço | I39: 540d55ff-f631-49e7-9563-f25d2fc32c9f
A40: 46166 | B40: Saída | D40: Não essencial | E40: Lanches | F40: 148.06 | G40: =IF(B40="Saída", -ABS(F40), ABS(F40)) -> -148.06 | H40: lanche pós culto | I40: 167a1611-005b-42fb-b552-253551424b45
...

Sheet JUNHO2026
A1: DATA | B1: TIPO | C1: DESCRIÇÃO | D1: CATEGORIA | E1: SUBCATEGORIA | F1: VALOR | G1: VALOR AJUSTADO | H1: OBSERVAÇÃO | I1: ID | J1: DASHBOARD JANEIRO | K1: VALOR | X1: FLUXO | Y1: NATUREZA | Z1: CATEGORIA_NOVA | AA1: SUBCATEGORIA_NOVA | AB1: ESSENCIALIDADE | AC1: COMPORTAMENTO | AD1: ID_MOVIMENTACAO_V2 | AE1: ID_META_V2 | AF1: STATUS_CLASSIFICACAO | AG1: PAGAMENTO_V2 | AH1: PARCELADO_V2 | AI1: QUANTIDADE_PARCELAS_V2 | AJ1: NUMERO_PARCELA_V2 | AL1: RESUMO DA CLASSIFICAÇÃO | AM1: VALOR
I2: 3f46ed0a-1d34-473d-be04-7b4ca5febc8d | J2: Entrada Total | K2: =SUMIF(B:B,"Entrada",G:G) -> 7076 | AL2: Receitas | AM2: =SUMIFS($F:$F,$X:$X,"Entrada",$Y:$Y,"Receita")+SUMIFS($F:$F,$B:$B,"Entrada",$X:$X,"") -> 7076
I3: f77db2c2-0557-4936-83df-2c4a543cb917 | J3: Saída Total | K3: =SUMIF(B:B,"Saída",G:G) -> 0 | AL3: Despesas | AM3: =SUMIFS($F:$F,$X:$X,"Saída",$Y:$Y,"Despesa")+SUMIFS($F:$F,$B:$B,"Saída",$X:$X,"",$D:$D,"<>Investimentos",$D:$D,"<>Sonhos") -> 0
I4: bc2cb344-0912-4174-acca-b1a9c58b1a61 | J4: Saldo | K4: =K2 + K3 -> 7076 | AL4: Despesas essenciais | AM4: =SUMIFS($F:$F,$X:$X,"Saída",$Y:$Y,"Despesa",$AB:$AB,"Essencial")+SUMIFS($F:$F,$B:$B,"Saída",$X:$X,"",$D:$D,"Essencial") -> 0
I5: e26e5f50-ee36-421c-8b94-c17dfa5b8d07 | AL5: Despesas não essenciais | AM5: =SUMIFS($F:$F,$X:$X,"Saída",$Y:$Y,"Despesa",$AB:$AB,"Não essencial")+SUMIFS($F:$F,$B:$B,"Saída",$X:$X,"",$D:$D,"Não essencial") -> 0
I6: c6c09571-6e0a-4dc6-b7fc-f0367e224534 | AL6: Investimentos | AM6: =SUMIFS($F:$F,$X:$X,"Saída",$Y:$Y,"Investimento")+SUMIFS($F:$F,$B:$B,"Saída",$X:$X,"",$D:$D,"Investimentos") -> 0
I7: c5a3ea4a-b56f-4e37-90d7-a721c47dc6ad | J7: Categoria | K7: Valor Real | M7: Categoria | N7: Valor planejado | O7: % Planejado | P7: Valor Real | Q7: Diferença | AL7: Aportes para sonhos | AM7: =SUMIFS($F:$F,$X:$X,"Saída",$Y:$Y,"Aporte para sonho")+SUMIFS($F:$F,$B:$B,"Saída",$X:$X,"",$D:$D,"Sonhos") -> 0
I8: ca5b28ab-2c50-4a88-8c1f-d518e1e17d9e | J8: Essencial | K8: =SUMIF($D:$D, J8, $F:$F) -> 0 | M8: Essencial | N8: =K2*O8 -> 3184.2 | O8: 0.45 | P8: =ABS(SUMIF(D:D, M8, F:F)) -> 0 | Q8: =P8 - N8 -> -3184.2 | AL8: Saldo financeiro | AM8: =SUMIFS($F:$F,$X:$X,"Entrada")-SUMIFS($F:$F,$X:$X,"Saída")+SUMIFS($F:$F,$B:$B,"Entrada",$X:$X,"")-SUMIFS($F:$F,$B:$B,"Saída",$X:$X,"") -> 7076
I9: ac54af3f-1f8d-48f0-8029-764df6356eb8 | J9: Não essencial | K9: =SUMIF($D:$D, J9, $F:$F) -> 0 | M9: Não essencial | N9: =K2*O9 -> 1415.2 | O9: 0.2 | P9: =ABS(SUMIF(D:D, M9, F:F)) -> 0 | Q9: =P9 - N9 -> -1415.2
I10: ee7325f5-d161-49fc-b93b-8898f9abcd92 | J10: Investimentos | K10: =SUMIF($D:$D, J10, $F:$F) -> 0 | M10: Investimentos | N10: =K2*O10 -> 2122.8 | O10: 0.3 | P10: =ABS(SUMIF(D:D, M10, F:F)) -> 0 | Q10: =P10 - N10 -> -2122.8
I11: f63b9533-2e76-4daf-bd43-82dd6e35969e | J11: Sonhos | K11: =SUMIF($D:$D, J11, $F:$F) -> 0 | M11: Sonhos | N11: =K2*O11 -> 353.8 | O11: 0.05 | P11: =ABS(SUMIF(D:D, M11, F:F)) -> 0 | Q11: =P11 - N11 -> -353.8
I12: e284f6e0-17f5-40cf-ae48-f4e3993d9ca5
I13: 11810d0d-0306-42bb-8f4f-93367f6a3b6f
I14: c3f6d488-67c9-4433-b490-e6ac009f5f6c
I15: 1898a670-3cf9-443e-af57-8859be183e72
I16: 4570d177-3260-4c49-8ef4-a7e59bd44513
I17: 9a47251d-afcc-4422-a630-03b3caeae27c
I18: 3c722536-bdf4-4623-b7f3-32f2acede515
I19: e4204e67-44a2-4b01-bd69-6349a549a452
I20: a6281297-ab35-48aa-ae82-ce55ebdc5912
I21: 263bd103-a5d5-41af-9eb4-348470223d21
I22: 8efc2b67-dd1c-46ed-bc08-62a838a8a111
I23: fc4946a6-a608-4774-9639-27073b04e1ac
... I29: 1a15b936-e3f6-49e8-a607-254f950f0584
G30: =IF(B30="Saída", -ABS(F30), ABS(F30)) -> 0 | I30: 83b93113-8e7f-447e-95d9-f7be51f02adf
G31: =IF(B31="Saída", -ABS(F31), ABS(F31)) -> 0 | I31: de7d4233-354b-43f4-9f11-94ad3df8f958
G32: =IF(B32="Saída", -ABS(F32), ABS(F32)) -> 0 | I32: 32a15779-968b-431d-bbcf-dd8c61a6c37d
G33: =IF(B33="Saída", -ABS(F33), ABS(F33)) -> 0 | I33: 28572384-e69b-4b62-8e85-4d8677cc65bf
G34: =IF(B34="Saída", -ABS(F34), ABS(F34)) -> 0 | I34: 100f3e7a-49dc-4685-9967-603ce8adace2
G35: =IF(B35="Saída", -ABS(F35), ABS(F35)) -> 0 | I35: ae00db5e-ccab-4e59-96b8-68b3ab7a8161
G36: =IF(B36="Saída", -ABS(F36), ABS(F36)) -> 0 | I36: c0c4133f-e87d-47a8-93c7-62a62abfce35
G37: =IF(B37="Saída", -ABS(F37), ABS(F37)) -> 0 | I37: e3155684-be54-4d02-a824-46b747188508
G38: =IF(B38="Saída", -ABS(F38), ABS(F38)) -> 0 | I38: 0d0eada0-fe30-46c5-9240-5ac09715f36b
G39: =IF(B39="Saída", -ABS(F39), ABS(F39)) -> 0 | I39: 6680c66c-6b55-4bb6-bd38-ba4a1f4309cb
G40: =IF(B40="Saída", -ABS(F40), ABS(F40)) -> 0 | I40: 37a56925-e973-4ff6-84d4-44ed4c489a97
G41: =IF(B41="Saída", -ABS(F41), ABS(F41)) -> 0 | I41: 74d4a10f-3526-4dfa-ac5e-02cd14a098de
... G49: =IF(B49="Saída", -ABS(F49), ABS(F49)) -> 0 | I49: b2167e4d-4f7b-4164-ad8a-8d5469e501d6
B50: Entrada | F50: 7076 | G50: =IF(B50="Saída", -ABS(F50), ABS(F50)) -> 7076 | I50: 993b2fd2-62d1-47f3-99ec-4ba87af98bb9

Sheet JULHO2026
A1: DATA | B1: TIPO | C1: DESCRIÇÃO | D1: CATEGORIA | E1: SUBCATEGORIA | F1: VALOR | G1: VALOR AJUSTADO | H1: OBSERVAÇÃO | I1: ID | J1: DASHBOARD JANEIRO | K1: VALOR | X1: FLUXO | Y1: NATUREZA | Z1: CATEGORIA_NOVA | AA1: SUBCATEGORIA_NOVA | AB1: ESSENCIALIDADE | AC1: COMPORTAMENTO | AD1: ID_MOVIMENTACAO_V2 | AE1: ID_META_V2 | AF1: STATUS_CLASSIFICACAO | AG1: PAGAMENTO_V2 | AH1: PARCELADO_V2 | AI1: QUANTIDADE_PARCELAS_V2 | AJ1: NUMERO_PARCELA_V2 | AL1: RESUMO DA CLASSIFICAÇÃO | AM1: VALOR
B2: Entrada | G2: =IF(B2="Saída", -ABS(F2), ABS(F2)) -> 0 | I2: bdc86593-3ae2-4935-a44b-4c8def51510e | J2: Entrada Total | K2: =SUMIF(B:B,"Entrada",G:G) -> 0 | AL2: Receitas | AM2: =SUMIFS($F:$F,$X:$X,"Entrada",$Y:$Y,"Receita")+SUMIFS($F:$F,$B:$B,"Entrada",$X:$X,"") -> 0
G3: =IF(B3="Saída", -ABS(F3), ABS(F3)) -> 0 | I3: 15098aee-31cf-4617-9b09-03e3ba558eeb | J3: Saída Total | K3: =SUMIF(B:B,"Saída",G:G) -> 0 | AL3: Despesas | AM3: =SUMIFS($F:$F,$X:$X,"Saída",$Y:$Y,"Despesa")+SUMIFS($F:$F,$B:$B,"Saída",$X:$X,"",$D:$D,"<>Investimentos",$D:$D,"<>Sonhos") -> 0
G4: =IF(B4="Saída", -ABS(F4), ABS(F4)) -> 0 | I4: 3e3d0706-391d-442b-8a48-778876d53273 | J4: Saldo | K4: =K2 + K3 -> 0 | AL4: Despesas essenciais | AM4: =SUMIFS($F:$F,$X:$X,"Saída",$Y:$Y,"Despesa",$AB:$AB,"Essencial")+SUMIFS($F:$F,$B:$B,"Saída",$X:$X,"",$D:$D,"Essencial") -> 0
G5: =IF(B5="Saída", -ABS(F5), ABS(F5)) -> 0 | I5: 9cfc39b0-ad82-4630-a2a0-05a919e8f31d | AL5: Despesas não essenciais | AM5: =SUMIFS($F:$F,$X:$X,"Saída",$Y:$Y,"Despesa",$AB:$AB,"Não essencial")+SUMIFS($F:$F,$B:$B,"Saída",$X:$X,"",$D:$D,"Não essencial") -> 0
G6: =IF(B6="Saída", -ABS(F6), ABS(F6)) -> 0 | I6: 5300f581-71d3-4834-a14a-18337cef4d98 | AL6: Investimentos | AM6: =SUMIFS($F:$F,$X:$X,"Saída",$Y:$Y,"Investimento")+SUMIFS($F:$F,$B:$B,"Saída",$X:$X,"",$D:$D,"Investimentos") -> 0
G7: =IF(B7="Saída", -ABS(F7), ABS(F7)) -> 0 | I7: e25273f1-982a-4679-b9dd-a3211026f727 | J7: Categoria | K7: Valor Real | M7: Categoria | N7: Valor planejado | O7: % Planejado | P7: Valor Real | Q7: Diferença | AL7: Aportes para sonhos | AM7: =SUMIFS($F:$F,$X:$X,"Saída",$Y:$Y,"Aporte para sonho")+SUMIFS($F:$F,$B:$B,"Saída",$X:$X,"",$D:$D,"Sonhos") -> 0
G8: =IF(B8="Saída", -ABS(F8), ABS(F8)) -> 0 | I8: 25162f74-2040-4d45-81ca-3f59e8e48f70 | J8: Essencial | K8: =SUMIF($D:$D, J8, $F:$F) -> 0 | M8: Essencial | N8: =K2*O8 -> 0 | O8: 0.45 | P8: =ABS(SUMIF(D:D, M8, F:F)) -> 0 | Q8: =P8 - N8 -> 0 | AL8: Saldo financeiro | AM8: =SUMIFS($F:$F,$X:$X,"Entrada")-SUMIFS($F:$F,$X:$X,"Saída")+SUMIFS($F:$F,$B:$B,"Entrada",$X:$X,"")-SUMIFS($F:$F,$B:$B,"Saída",$X:$X,"") -> 0
G9: =IF(B9="Saída", -ABS(F9), ABS(F9)) -> 0 | I9: 40cf96de-9594-4b11-bcb3-438b13b77492 | J9: Não essencial | K9: =SUMIF($D:$D, J9, $F:$F) -> 0 | M9: Não essencial | N9: =K2*O9 -> 0 | O9: 0.2 | P9: =ABS(SUMIF(D:D, M9, F:F)) -> 0 | Q9: =P9 - N9 -> 0
G10: =IF(B10="Saída", -ABS(F10), ABS(F10)) -> 0 | I10: 2d8a37a3-14f7-4156-83b0-81819cfb1796 | J10: Investimentos | K10: =SUMIF($D:$D, J10, $F:$F) -> 0 | M10: Investimentos | N10: =K2*O10 -> 0 | O10: 0.3 | P10: =ABS(SUMIF(D:D, M10, F:F)) -> 0 | Q10: =P10 - N10 -> 0
G11: =IF(B11="Saída", -ABS(F11), ABS(F11)) -> 0 | I11: c0116120-a404-4f10-bbde-45e17e6ff86b | J11: Sonhos | K11: =SUMIF($D:$D, J11, $F:$F) -> 0 | M11: Sonhos | N11: =K2*O11 -> 0 | O11: 0.05 | P11: =ABS(SUMIF(D:D, M11, F:F)) -> 0 | Q11: =P11 - N11 -> 0
G12: =IF(B12="Saída", -ABS(F12), ABS(F12)) -> 0 | I12: bef40aea-c280-45be-91ee-f293a6d4729f
G13: =IF(B13="Saída", -ABS(F13), ABS(F13)) -> 0 | I13: e8e613c2-e5dd-4e55-8474-b509ef7e83fd
G14: =IF(B14="Saída", -ABS(F14), ABS(F14)) -> 0 | I14: 2db3caac-25a2-40c5-9c59-5e48f3f5655f
G15: =IF(B15="Saída", -ABS(F15), ABS(F15)) -> 0 | I15: 8ed95073-82f6-4dee-a877-fd033c759e17
G16: =IF(B16="Saída", -ABS(F16), ABS(F16)) -> 0 | I16: 5a3a549b-a62f-4dd7-9f98-596cc4d1e189
G17: =IF(B17="Saída", -ABS(F17), ABS(F17)) -> 0 | I17: e16238a6-e0e5-4683-b9e9-b02a21e89371
G18: =IF(B18="Saída", -ABS(F18), ABS(F18)) -> 0 | I18: 8a889498-d524-451b-837b-ea23f25545cc
G19: =IF(B19="Saída", -ABS(F19), ABS(F19)) -> 0 | I19: f2b0ea56-cbd4-4742-9173-3f9a9f3c869b
G20: =IF(B20="Saída", -ABS(F20), ABS(F20)) -> 0 | I20: 4f8c1911-af30-463a-b089-d22b5798ba13
G21: =IF(B21="Saída", -ABS(F21), ABS(F21)) -> 0 | I21: ab7fa04e-872c-49c2-84ec-590cf46156ab
G22: =IF(B22="Saída", -ABS(F22), ABS(F22)) -> 0 | I22: 4d1eb049-87d9-45cb-ad79-b2acdf4b32b1
G23: =IF(B23="Saída", -ABS(F23), ABS(F23)) -> 0 | I23: d0772e39-f82a-4d29-a99b-51bf31007630
... G231: =IF(B231="Saída", -ABS(F231), ABS(F231)) -> 0 | I231: 7ac8001f-2c64-4b73-bb2a-05517de5fd8d

Sheet AGOSTO2026
A1: DATA | B1: TIPO | C1: PAGAMENTO | D1: CATEGORIA | E1: SUBCATEGORIA | F1: VALOR | G1: VALOR AJUSTADO | H1: OBSERVAÇÃO | I1: ID | J1: DASHBOARD JANEIRO | K1: VALOR | X1: FLUXO | Y1: NATUREZA | Z1: CATEGORIA_NOVA | AA1: SUBCATEGORIA_NOVA | AB1: ESSENCIALIDADE | AC1: COMPORTAMENTO | AD1: ID_MOVIMENTACAO_V2 | AE1: ID_META_V2 | AF1: STATUS_CLASSIFICACAO | AG1: PAGAMENTO_V2 | AH1: PARCELADO_V2 | AI1: QUANTIDADE_PARCELAS_V2 | AJ1: NUMERO_PARCELA_V2 | AL1: RESUMO DA CLASSIFICAÇÃO | AM1: VALOR
A2: 46262.787 | B2: Entrada | C2: À vista | D2: Essencial | E2: Outros | F2: 51.99 | G2: =IF(B2="Saída", -ABS(F2), ABS(F2)) -> 51.99 | H2: Ajuste de saldo | I2: 5555b54f-ca50-40ed-95c2-34c22b122550 | J2: Entrada Total | K2: =SUMIF(B:B,"Entrada",G:G) -> 7228.79 | AL2: Receitas | AM2: =SUMIFS($F:$F,$X:$X,"Entrada",$Y:$Y,"Receita")+SUMIFS($F:$F,$B:$B,"Entrada",$X:$X,"") -> 7228.79
A3: 46235.787 | B3: SAÍDA | C3: Parcelado | D3: Essencial | E3: Carro | F3: 126.66 | G3: =IF(B3="Saída", -ABS(F3), ABS(F3)) -> -126.66 | H3: Revisão do carro | I3: 55982352-e1c8-401c-9957-e25cff43e0ed | J3: Saída Total | K3: =SUMIF(B:B,"Saída",G:G) -> -7804.68 | AL3: Despesas | AM3: =SUMIFS($F:$F,$X:$X,"Saída",$Y:$Y,"Despesa")+SUMIFS($F:$F,$B:$B,"Saída",$X:$X,"",$D:$D,"<>Investimentos",$D:$D,"<>Sonhos") -> 7588.01
A4: 46235.787 | B4: Saída | C4: Parcelado | D4: Não essencial | E4: Outros | F4: 52.11 | G4: =IF(B4="Saída", -ABS(F4), ABS(F4)) -> -52.11 | I4: e9739759-ded0-400d-89fd-a6a2a0e08bd9 | J4: Saldo | K4: =K2 + K3 -> -575.89 | U4: gasolina | V4: 657.1 | AL4: Despesas essenciais | AM4: =SUMIFS($F:$F,$X:$X,"Saída",$Y:$Y,"Despesa",$AB:$AB,"Essencial")+SUMIFS($F:$F,$B:$B,"Saída",$X:$X,"",$D:$D,"Essencial") -> 5931.88
A5: 46235.79 | B5: SAÍDA | D5: Não Essencial | E5: Outros | F5: 53.78 | G5: =IF(B5="Saída", -ABS(F5), ABS(F5)) -> -53.78 | H5: Itens do JIPOM | I5: 60a95e9b-4d67-49a4-a6c9-f51bd397f152 | AL5: Despesas não essenciais | AM5: =SUMIFS($F:$F,$X:$X,"Saída",$Y:$Y,"Despesa",$AB:$AB,"Não essencial")+SUMIFS($F:$F,$B:$B,"Saída",$X:$X,"",$D:$D,"Não essencial") -> 1656.13
A6: 46235.791 | B6: SAÍDA | D6: Essencial | E6: Gasolina | F6: 20 | G6: =IF(B6="Saída", -ABS(F6), ABS(F6)) -> -20 | H6: Referente a mês julho | I6: 0ad3b283-d594-4f58-b872-b544aee5d677 | AL6: Investimentos | AM6: =SUMIFS($F:$F,$X:$X,"Saída",$Y:$Y,"Investimento")+SUMIFS($F:$F,$B:$B,"Saída",$X:$X,"",$D:$D,"Investimentos") -> 250
A7: 46235.791 | B7: SAÍDA | D7: Não Essencial | E7: Outros | F7: 2.99 | G7: =IF(B7="Saída", -ABS(F7), ABS(F7)) -> -2.99 | H7: Itens Jipom | I7: 93c6d9b7-4eaf-4278-af0a-f05416992718 | J7: Categoria | K7: Valor Real | M7: Categoria | N7: Valor planejado | O7: % Planejado | P7: Valor Real | Q7: Diferença | AL7: Aportes para sonhos | AM7: =SUMIFS($F:$F,$X:$X,"Saída",$Y:$Y,"Aporte para sonho")+SUMIFS($F:$F,$B:$B,"Saída",$X:$X,"",$D:$D,"Sonhos") -> 0
A8: 46235.791 | B8: SAÍDA | D8: Não Essencial | E8: Lanches | F8: 14 | G8: =IF(B8="Saída", -ABS(F8), ABS(F8)) -> -14 | I8: f3c4fb30-4e5b-4763-96be-b42f3f43f55c | J8: Essencial | K8: =SUMIFS($F:$F,$D:$D,J8,$E:$E,"<>Salário") -> 5983.87 | M8: Essencial | N8: =K2*O8 -> 3252.9555 | O8: 0.45 | P8: =ABS(SUMIF(D:D, M8, F:F)) -> 13160.67 | Q8: =P8 - N8 -> 9907.7145 | AL8: Saldo financeiro | AM8: =SUMIFS($F:$F,$X:$X,"Entrada")-SUMIFS($F:$F,$X:$X,"Saída")+SUMIFS($F:$F,$B:$B,"Entrada",$X:$X,"")-SUMIFS($F:$F,$B:$B,"Saída",$X:$X,"") -> -609.22
A9: 46235.792 | B9: SAÍDA | D9: Não Essencial | E9: Outros | F9: 50 | G9: =IF(B9="Saída", -ABS(F9), ABS(F9)) -> -50 | I9: 45f2737b-622d-484d-b0a9-820be547eeb8 | J9: Não essencial | K9: =SUMIF($D:$D, J9, $F:$F) -> 1656.13 | M9: Não essencial | N9: =K2*O9 -> 1445.758 | O9: 0.2 | P9: =ABS(SUMIF(D:D, M9, F:F)) -> 1656.13 | Q9: =P9 - N9 -> 210.372
A10: 46235.793 | B10: SAÍDA | D10: Essencial | E10: Gasolina | F10: 162.13 | G10: =IF(B10="Saída", -ABS(F10), ABS(F10)) -> -162.13 | H10: Referente a agosto. Tanque cheio | I10: 9cb6f3a5-da4d-4f36-a94b-523f71121fc8 | J10: Investimentos | K10: =SUMIF($D:$D, J10, $F:$F) -> 250 | M10: Investimentos | N10: =K2*O10 -> 2168.637 | O10: 0.3 | P10: =ABS(SUMIF(D:D, M10, F:F)) -> 250 | Q10: =P10 - N10 -> -1918.637
A11: 46235.793 | B11: SAÍDA | D11: Não Essencial | E11: Outros | F11: 7 | G11: =IF(B11="Saída", -ABS(F11), ABS(F11)) -> -7 | H11: Itens jipom | I11: dafc0cc5-6104-485c-b436-69dacbecaefb | J11: Sonhos | K11: =SUMIF($D:$D, J11, $F:$F) -> 0 | M11: Sonhos | N11: =K2*O11 -> 361.4395 | O11: 0.05 | P11: =ABS(SUMIF(D:D, M11, F:F)) -> 0 | Q11: =P11 - N11 -> -361.4395
A12: 46235.794 | B12: SAÍDA | D12: Não Essencial | E12: Restaurante | F12: 45 | G12: =IF(B12="Saída", -ABS(F12), ABS(F12)) -> -45 | H12: Frango para almoçar com avós | I12: 1221fd6e-ead8-4194-9509-16d284f77acd
A13: 46235.795 | B13: SAÍDA | D13: Não Essencial | E13: Outros | F13: 7.9 | G13: =IF(B13="Saída", -ABS(F13), ABS(F13)) -> -7.9 | H13: Itens jipom | I13: 6dcda194-1fd2-4867-b1bc-55bfb046b191
A14: 46235.795 | B14: SAÍDA | D14: Essencial | E14: Curso | F14: 24.9 | G14: =IF(B14="Saída", -ABS(F14), ABS(F14)) -> -24.9 | H14: assinatura qconcursos | I14: be6f98be-331b-436c-b66c-9296423c2e35
A15: 46235.795 | B15: SAÍDA | D15: Essencial | E15: Outros | F15: 399.9 | G15: =IF(B15="Saída", -ABS(F15), ABS(F15)) -> -399.9 | H15: parcela celular | I15: 4fb19822-66dc-4739-9433-3efe3058574d
A16: 46235.795 | B16: SAÍDA | D16: Essencial | E16: Carro | F16: 294.32 | G16: =IF(B16="Saída", -ABS(F16), ABS(F16)) -> -294.32 | H16: seguro carro | I16: 8ea64ba2-1a00-42d4-a08e-d1cad115a11f
A17: 46235.795 | B17: SAÍDA | D17: Essencial | E17: Carro | F17: 1500 | G17: =IF(B17="Saída", -ABS(F17), ABS(F17)) -> -1500 | H17: parcela carro | I17: d5936cfe-cbdd-435a-aadc-238d9cb7468e
A18: 46235.795 | B18: SAÍDA | D18: Essencial | E18: Outros | F18: 707.68 | G18: =IF(B18="Saída", -ABS(F18), ABS(F18)) -> -707.68 | H18: Dízimo | I18: 59ef935b-34ea-4de5-9ed6-93385a53e218
A19: 46235.795 | B19: SAÍDA | D19: Essencial | E19: Equipamento | F19: 1000 | G19: =IF(B19="Saída", -ABS(F19), ABS(F19)) -> -1000 | H19: notbook | I19: 2b596094-9089-4e5c-a524-e59147b740e7
A20: 46235.795 | B20: SAÍDA | D20: Investimentos | E20: Casamento | F20: 250 | G20: =IF(B20="Saída", -ABS(F20), ABS(F20)) -> -250 | I20: 4b3dac66-7638-4b24-ba33-ec71088bad3b
